2021-07-02 15:18:45,889 ERROR: Exception on /seguimiento [GET] [in c:\users\user\anaconda3\envs\web\lib\site-packages\flask\app.py:1454]
Traceback (most recent call last):
  File "c:\users\user\anaconda3\envs\web\lib\site-packages\flask\app.py", line 2070, in wsgi_app
    response = self.full_dispatch_request()
  File "c:\users\user\anaconda3\envs\web\lib\site-packages\flask\app.py", line 1515, in full_dispatch_request
    rv = self.handle_user_exception(e)
  File "c:\users\user\anaconda3\envs\web\lib\site-packages\flask\app.py", line 1513, in full_dispatch_request
    rv = self.dispatch_request()
  File "c:\users\user\anaconda3\envs\web\lib\site-packages\flask\app.py", line 1499, in dispatch_request
    return self.ensure_sync(self.view_functions[rule.endpoint])(**req.view_args)
  File "c:\users\user\anaconda3\envs\web\lib\site-packages\flask_login\utils.py", line 272, in decorated_view
    return func(*args, **kwargs)
  File "C:\Users\user\Desktop\MTS\app\main\routes.py", line 275, in seguimiento
    return render_template('seguimiento.html',title=_('Seguimiento'), user=user.items, consultas = consultas,
  File "c:\users\user\anaconda3\envs\web\lib\site-packages\flask\templating.py", line 147, in render_template
    return _render(
  File "c:\users\user\anaconda3\envs\web\lib\site-packages\flask\templating.py", line 128, in _render
    rv = template.render(context)
  File "c:\users\user\anaconda3\envs\web\lib\site-packages\jinja2\environment.py", line 1090, in render
    self.environment.handle_exception()
  File "c:\users\user\anaconda3\envs\web\lib\site-packages\jinja2\environment.py", line 832, in handle_exception
    reraise(*rewrite_traceback_stack(source=source))
  File "c:\users\user\anaconda3\envs\web\lib\site-packages\jinja2\_compat.py", line 28, in reraise
    raise value.with_traceback(tb)
  File "C:\Users\user\Desktop\MTS\app\templates\seguimiento.html", line 2, in top-level template code
    {% import 'bootstrap/wtf.html' as wtf %}
  File "C:\Users\user\Desktop\MTS\app\templates\base.html", line 1, in top-level template code
    {% extends 'bootstrap/base.html' %}
  File "c:\users\user\anaconda3\envs\web\lib\site-packages\flask_bootstrap\templates\bootstrap\base.html", line 1, in top-level template code
    {% block doc -%}
  File "c:\users\user\anaconda3\envs\web\lib\site-packages\flask_bootstrap\templates\bootstrap\base.html", line 4, in block "doc"
    {%- block html %}
  File "c:\users\user\anaconda3\envs\web\lib\site-packages\flask_bootstrap\templates\bootstrap\base.html", line 20, in block "html"
    {% block body -%}
  File "c:\users\user\anaconda3\envs\web\lib\site-packages\flask_bootstrap\templates\bootstrap\base.html", line 23, in block "body"
    {% block content -%}
  File "C:\Users\user\Desktop\MTS\app\templates\base.html", line 90, in block "content"
    {% block app_content %}{% endblock %}
  File "C:\Users\user\Desktop\MTS\app\templates\seguimiento.html", line 38, in block "app_content"
    {% include '_usuarios.html' %}
  File "C:\Users\user\Desktop\MTS\app\templates\_usuarios.html", line 25, in top-level template code
    {{ _('Un %(verdes)s son verdes, un %(amarillas)s son amarillas y un %(rojas)s de las evaluaciones son Rojas.', verdes=consultas.query.filter_by(user_id = user.id and consultas.score_final >= 666).count(), amarillas=consultas.query.filter_by(user_id = user.id and consultas.score_final <666 and consultas.score_final >=333).count(), rojas=consultas.query.filter_by(user_id = user.id and consultas.score_final < 333).count()) }}
  File "c:\users\user\anaconda3\envs\web\lib\site-packages\sqlalchemy\sql\elements.py", line 3714, in __bool__
    raise TypeError("Boolean value of this clause is not defined")
TypeError: Boolean value of this clause is not defined
2021-07-02 15:19:14,365 INFO: Evaluador startup [in C:\Users\user\Desktop\MTS\app\__init__.py:97]
2021-07-02 15:20:15,166 INFO: Evaluador startup [in C:\Users\user\Desktop\MTS\app\__init__.py:97]
2021-07-02 15:20:32,760 INFO: Evaluador startup [in C:\Users\user\Desktop\MTS\app\__init__.py:97]
2021-07-02 15:20:33,696 ERROR: Exception on /seguimiento [GET] [in c:\users\user\anaconda3\envs\web\lib\site-packages\flask\app.py:1454]
Traceback (most recent call last):
  File "c:\users\user\anaconda3\envs\web\lib\site-packages\flask\app.py", line 2070, in wsgi_app
    response = self.full_dispatch_request()
  File "c:\users\user\anaconda3\envs\web\lib\site-packages\flask\app.py", line 1515, in full_dispatch_request
    rv = self.handle_user_exception(e)
  File "c:\users\user\anaconda3\envs\web\lib\site-packages\flask\app.py", line 1513, in full_dispatch_request
    rv = self.dispatch_request()
  File "c:\users\user\anaconda3\envs\web\lib\site-packages\flask\app.py", line 1499, in dispatch_request
    return self.ensure_sync(self.view_functions[rule.endpoint])(**req.view_args)
  File "c:\users\user\anaconda3\envs\web\lib\site-packages\flask_login\utils.py", line 272, in decorated_view
    return func(*args, **kwargs)
  File "C:\Users\user\Desktop\MTS\app\main\routes.py", line 275, in seguimiento
    return render_template('seguimiento.html',title=_('Seguimiento'), user=user.items, consultas = consultas,
  File "c:\users\user\anaconda3\envs\web\lib\site-packages\flask\templating.py", line 147, in render_template
    return _render(
  File "c:\users\user\anaconda3\envs\web\lib\site-packages\flask\templating.py", line 128, in _render
    rv = template.render(context)
  File "c:\users\user\anaconda3\envs\web\lib\site-packages\jinja2\environment.py", line 1090, in render
    self.environment.handle_exception()
  File "c:\users\user\anaconda3\envs\web\lib\site-packages\jinja2\environment.py", line 832, in handle_exception
    reraise(*rewrite_traceback_stack(source=source))
  File "c:\users\user\anaconda3\envs\web\lib\site-packages\jinja2\_compat.py", line 28, in reraise
    raise value.with_traceback(tb)
  File "C:\Users\user\Desktop\MTS\app\templates\seguimiento.html", line 2, in top-level template code
    {% import 'bootstrap/wtf.html' as wtf %}
  File "C:\Users\user\Desktop\MTS\app\templates\base.html", line 1, in top-level template code
    {% extends 'bootstrap/base.html' %}
  File "c:\users\user\anaconda3\envs\web\lib\site-packages\flask_bootstrap\templates\bootstrap\base.html", line 1, in top-level template code
    {% block doc -%}
  File "c:\users\user\anaconda3\envs\web\lib\site-packages\flask_bootstrap\templates\bootstrap\base.html", line 4, in block "doc"
    {%- block html %}
  File "c:\users\user\anaconda3\envs\web\lib\site-packages\flask_bootstrap\templates\bootstrap\base.html", line 20, in block "html"
    {% block body -%}
  File "c:\users\user\anaconda3\envs\web\lib\site-packages\flask_bootstrap\templates\bootstrap\base.html", line 23, in block "body"
    {% block content -%}
  File "C:\Users\user\Desktop\MTS\app\templates\base.html", line 90, in block "content"
    {% block app_content %}{% endblock %}
  File "C:\Users\user\Desktop\MTS\app\templates\seguimiento.html", line 38, in block "app_content"
    {% include '_usuarios.html' %}
  File "c:\users\user\anaconda3\envs\web\lib\site-packages\jinja2\environment.py", line 832, in handle_exception
    reraise(*rewrite_traceback_stack(source=source))
  File "c:\users\user\anaconda3\envs\web\lib\site-packages\jinja2\_compat.py", line 28, in reraise
    raise value.with_traceback(tb)
  File "C:\Users\user\Desktop\MTS\app\templates\_usuarios.html", line 25, in template
    {{ _('Un %(verdes)s son verdes, un %(amarillas)s son amarillas y un %(rojas)s de las evaluaciones son Rojas.', verdes=consultas.query.filter_by(user_id = user.id and consultas.score_final >= 666).count(), amarillas=1, rojas=consultas.query.filter_by((consultas.user_id = user.id and consultas.score_final < 333)).count()) }}
jinja2.exceptions.TemplateSyntaxError: expected token ')', got '='
2021-07-02 15:20:44,203 INFO: Evaluador startup [in C:\Users\user\Desktop\MTS\app\__init__.py:97]
