2021-06-29 11:02:06,314 ERROR: Exception on /historial [GET] [in c:\users\user\anaconda3\envs\web\lib\site-packages\flask\app.py:1454]
Traceback (most recent call last):
  File "c:\users\user\anaconda3\envs\web\lib\site-packages\flask\app.py", line 2070, in wsgi_app
    response = self.full_dispatch_request()
  File "c:\users\user\anaconda3\envs\web\lib\site-packages\flask\app.py", line 1515, in full_dispatch_request
    rv = self.handle_user_exception(e)
  File "c:\users\user\anaconda3\envs\web\lib\site-packages\flask\app.py", line 1513, in full_dispatch_request
    rv = self.dispatch_request()
  File "c:\users\user\anaconda3\envs\web\lib\site-packages\flask\app.py", line 1499, in dispatch_request
    return self.ensure_sync(self.view_functions[rule.endpoint])(**req.view_args)
  File "c:\users\user\anaconda3\envs\web\lib\site-packages\flask_login\utils.py", line 272, in decorated_view
    return func(*args, **kwargs)
  File "C:\Users\user\Desktop\MTS\app\main\routes.py", line 241, in historial
    return render_template('historial.html',title=_('Historial Consultas'), consultas=consultas.items,
  File "c:\users\user\anaconda3\envs\web\lib\site-packages\flask\templating.py", line 147, in render_template
    return _render(
  File "c:\users\user\anaconda3\envs\web\lib\site-packages\flask\templating.py", line 128, in _render
    rv = template.render(context)
  File "c:\users\user\anaconda3\envs\web\lib\site-packages\jinja2\environment.py", line 1090, in render
    self.environment.handle_exception()
  File "c:\users\user\anaconda3\envs\web\lib\site-packages\jinja2\environment.py", line 832, in handle_exception
    reraise(*rewrite_traceback_stack(source=source))
  File "c:\users\user\anaconda3\envs\web\lib\site-packages\jinja2\_compat.py", line 28, in reraise
    raise value.with_traceback(tb)
  File "C:\Users\user\Desktop\MTS\app\templates\historial.html", line 2, in top-level template code
    {% import 'bootstrap/wtf.html' as wtf %}
  File "C:\Users\user\Desktop\MTS\app\templates\base.html", line 1, in top-level template code
    {% extends 'bootstrap/base.html' %}
  File "c:\users\user\anaconda3\envs\web\lib\site-packages\flask_bootstrap\templates\bootstrap\base.html", line 1, in top-level template code
    {% block doc -%}
  File "c:\users\user\anaconda3\envs\web\lib\site-packages\flask_bootstrap\templates\bootstrap\base.html", line 4, in block "doc"
    {%- block html %}
  File "c:\users\user\anaconda3\envs\web\lib\site-packages\flask_bootstrap\templates\bootstrap\base.html", line 20, in block "html"
    {% block body -%}
  File "c:\users\user\anaconda3\envs\web\lib\site-packages\flask_bootstrap\templates\bootstrap\base.html", line 23, in block "body"
    {% block content -%}
  File "C:\Users\user\Desktop\MTS\app\templates\base.html", line 90, in block "content"
    {% block app_content %}{% endblock %}
  File "C:\Users\user\Desktop\MTS\app\templates\historial.html", line 51, in block "app_content"
    {% if consultas.score_final < 333 %}
TypeError: '<' not supported between instances of 'NoneType' and 'int'
2021-06-29 11:05:56,432 INFO: Microblog startup [in C:\Users\user\Desktop\MTS\app\__init__.py:97]
2021-06-29 11:06:07,373 ERROR: Exception on /historial [GET] [in c:\users\user\anaconda3\envs\web\lib\site-packages\flask\app.py:1454]
Traceback (most recent call last):
  File "c:\users\user\anaconda3\envs\web\lib\site-packages\flask\app.py", line 2070, in wsgi_app
    response = self.full_dispatch_request()
  File "c:\users\user\anaconda3\envs\web\lib\site-packages\flask\app.py", line 1515, in full_dispatch_request
    rv = self.handle_user_exception(e)
  File "c:\users\user\anaconda3\envs\web\lib\site-packages\flask\app.py", line 1513, in full_dispatch_request
    rv = self.dispatch_request()
  File "c:\users\user\anaconda3\envs\web\lib\site-packages\flask\app.py", line 1499, in dispatch_request
    return self.ensure_sync(self.view_functions[rule.endpoint])(**req.view_args)
  File "c:\users\user\anaconda3\envs\web\lib\site-packages\flask_login\utils.py", line 272, in decorated_view
    return func(*args, **kwargs)
  File "C:\Users\user\Desktop\MTS\app\main\routes.py", line 242, in historial
    return render_template('historial.html',title=_('Historial Consultas'), consultas=consultas.items,
  File "c:\users\user\anaconda3\envs\web\lib\site-packages\flask\templating.py", line 147, in render_template
    return _render(
  File "c:\users\user\anaconda3\envs\web\lib\site-packages\flask\templating.py", line 128, in _render
    rv = template.render(context)
  File "c:\users\user\anaconda3\envs\web\lib\site-packages\jinja2\environment.py", line 1090, in render
    self.environment.handle_exception()
  File "c:\users\user\anaconda3\envs\web\lib\site-packages\jinja2\environment.py", line 832, in handle_exception
    reraise(*rewrite_traceback_stack(source=source))
  File "c:\users\user\anaconda3\envs\web\lib\site-packages\jinja2\_compat.py", line 28, in reraise
    raise value.with_traceback(tb)
  File "C:\Users\user\Desktop\MTS\app\templates\historial.html", line 2, in top-level template code
    {% import 'bootstrap/wtf.html' as wtf %}
  File "C:\Users\user\Desktop\MTS\app\templates\base.html", line 1, in top-level template code
    {% extends 'bootstrap/base.html' %}
  File "c:\users\user\anaconda3\envs\web\lib\site-packages\flask_bootstrap\templates\bootstrap\base.html", line 1, in top-level template code
    {% block doc -%}
  File "c:\users\user\anaconda3\envs\web\lib\site-packages\flask_bootstrap\templates\bootstrap\base.html", line 4, in block "doc"
    {%- block html %}
  File "c:\users\user\anaconda3\envs\web\lib\site-packages\flask_bootstrap\templates\bootstrap\base.html", line 20, in block "html"
    {% block body -%}
  File "c:\users\user\anaconda3\envs\web\lib\site-packages\flask_bootstrap\templates\bootstrap\base.html", line 23, in block "body"
    {% block content -%}
  File "C:\Users\user\Desktop\MTS\app\templates\base.html", line 90, in block "content"
    {% block app_content %}{% endblock %}
  File "C:\Users\user\Desktop\MTS\app\templates\historial.html", line 51, in block "app_content"
    {% if consultas.score_final < 333 %}
TypeError: '<' not supported between instances of 'NoneType' and 'int'
2021-06-29 11:35:41,499 INFO: Microblog startup [in C:\Users\user\Desktop\MTS\app\__init__.py:97]
2021-06-29 11:35:49,466 ERROR: Exception on /Consulta-9 [GET] [in c:\users\user\anaconda3\envs\web\lib\site-packages\flask\app.py:1454]
Traceback (most recent call last):
  File "c:\users\user\anaconda3\envs\web\lib\site-packages\flask\app.py", line 2070, in wsgi_app
    response = self.full_dispatch_request()
  File "c:\users\user\anaconda3\envs\web\lib\site-packages\flask\app.py", line 1515, in full_dispatch_request
    rv = self.handle_user_exception(e)
  File "c:\users\user\anaconda3\envs\web\lib\site-packages\flask\app.py", line 1513, in full_dispatch_request
    rv = self.dispatch_request()
  File "c:\users\user\anaconda3\envs\web\lib\site-packages\flask\app.py", line 1499, in dispatch_request
    return self.ensure_sync(self.view_functions[rule.endpoint])(**req.view_args)
  File "c:\users\user\anaconda3\envs\web\lib\site-packages\flask_login\utils.py", line 272, in decorated_view
    return func(*args, **kwargs)
  File "C:\Users\user\Desktop\MTS\app\main\routes.py", line 291, in evaluacion
    consulta_rut = consultarut(consultaid, base)[0]
  File "c:\users\user\anaconda3\envs\web\lib\site-packages\consultas.py", line 158, in consultarut
    return list(rut, id_buscado)
TypeError: list expected at most 1 argument, got 2
2021-06-29 11:40:10,261 INFO: Microblog startup [in C:\Users\user\Desktop\MTS\app\__init__.py:97]
2021-06-29 11:42:00,207 INFO: Microblog startup [in C:\Users\user\Desktop\MTS\app\__init__.py:97]
2021-06-29 11:43:30,500 INFO: Microblog startup [in C:\Users\user\Desktop\MTS\app\__init__.py:97]
2021-06-29 12:02:01,410 INFO: Microblog startup [in C:\Users\user\Desktop\MTS\app\__init__.py:97]
2021-06-29 12:02:37,611 INFO: Microblog startup [in C:\Users\user\Desktop\MTS\app\__init__.py:97]
2021-06-29 12:03:36,326 INFO: Microblog startup [in C:\Users\user\Desktop\MTS\app\__init__.py:97]
2021-06-29 12:05:14,471 INFO: Microblog startup [in C:\Users\user\Desktop\MTS\app\__init__.py:97]
2021-06-29 12:05:34,790 INFO: Microblog startup [in C:\Users\user\Desktop\MTS\app\__init__.py:97]
2021-06-29 12:11:40,445 INFO: Microblog startup [in C:\Users\user\Desktop\MTS\app\__init__.py:97]
2021-06-29 12:11:59,811 INFO: Microblog startup [in C:\Users\user\Desktop\MTS\app\__init__.py:97]
2021-06-29 12:12:25,264 INFO: Microblog startup [in C:\Users\user\Desktop\MTS\app\__init__.py:97]
2021-06-29 12:13:39,825 INFO: Microblog startup [in C:\Users\user\Desktop\MTS\app\__init__.py:97]
2021-06-29 12:14:28,408 INFO: Microblog startup [in C:\Users\user\Desktop\MTS\app\__init__.py:97]
2021-06-29 13:01:27,658 INFO: Microblog startup [in C:\Users\user\Desktop\MTS\app\__init__.py:97]
