2021-06-28 16:14:01,285 ERROR: Exception on /gestion [POST] [in c:\users\user\anaconda3\envs\web\lib\site-packages\flask\app.py:1454]
Traceback (most recent call last):
  File "c:\users\user\anaconda3\envs\web\lib\site-packages\flask\app.py", line 2070, in wsgi_app
    response = self.full_dispatch_request()
  File "c:\users\user\anaconda3\envs\web\lib\site-packages\flask\app.py", line 1515, in full_dispatch_request
    rv = self.handle_user_exception(e)
  File "c:\users\user\anaconda3\envs\web\lib\site-packages\flask\app.py", line 1513, in full_dispatch_request
    rv = self.dispatch_request()
  File "c:\users\user\anaconda3\envs\web\lib\site-packages\flask\app.py", line 1499, in dispatch_request
    return self.ensure_sync(self.view_functions[rule.endpoint])(**req.view_args)
  File "c:\users\user\anaconda3\envs\web\lib\site-packages\flask_login\utils.py", line 272, in decorated_view
    return func(*args, **kwargs)
  File "C:\Users\user\Desktop\MTS\app\main\routes.py", line 42, in decorated_function
    return f(*args, **kws)
  File "C:\Users\user\Desktop\MTS\app\main\routes.py", line 301, in gestion
    return redirect(url_for('main.ejecutivos'))
  File "c:\users\user\anaconda3\envs\web\lib\site-packages\flask\helpers.py", line 338, in url_for
    return appctx.app.handle_url_build_error(error, endpoint, values)
  File "c:\users\user\anaconda3\envs\web\lib\site-packages\flask\helpers.py", line 325, in url_for
    rv = url_adapter.build(
  File "c:\users\user\anaconda3\envs\web\lib\site-packages\werkzeug\routing.py", line 2305, in build
    raise BuildError(endpoint, values, method, self)
werkzeug.routing.BuildError: Could not build url for endpoint 'main.ejecutivos'. Did you mean 'main.gestion' instead?
2021-06-28 16:15:15,062 INFO: Microblog startup [in C:\Users\user\Desktop\MTS\app\__init__.py:97]
2021-06-28 16:15:46,705 INFO: Microblog startup [in C:\Users\user\Desktop\MTS\app\__init__.py:97]
2021-06-28 16:15:56,454 INFO: Microblog startup [in C:\Users\user\Desktop\MTS\app\__init__.py:97]
2021-06-28 16:16:04,941 ERROR: Exception on /gestion [POST] [in c:\users\user\anaconda3\envs\web\lib\site-packages\flask\app.py:1454]
Traceback (most recent call last):
  File "c:\users\user\anaconda3\envs\web\lib\site-packages\flask\app.py", line 2070, in wsgi_app
    response = self.full_dispatch_request()
  File "c:\users\user\anaconda3\envs\web\lib\site-packages\flask\app.py", line 1515, in full_dispatch_request
    rv = self.handle_user_exception(e)
  File "c:\users\user\anaconda3\envs\web\lib\site-packages\flask\app.py", line 1513, in full_dispatch_request
    rv = self.dispatch_request()
  File "c:\users\user\anaconda3\envs\web\lib\site-packages\flask\app.py", line 1499, in dispatch_request
    return self.ensure_sync(self.view_functions[rule.endpoint])(**req.view_args)
  File "c:\users\user\anaconda3\envs\web\lib\site-packages\flask_login\utils.py", line 272, in decorated_view
    return func(*args, **kwargs)
  File "C:\Users\user\Desktop\MTS\app\main\routes.py", line 42, in decorated_function
    return f(*args, **kws)
  File "C:\Users\user\Desktop\MTS\app\main\routes.py", line 301, in gestion
    return redirect(url_for('main.ejecutivos'))
  File "c:\users\user\anaconda3\envs\web\lib\site-packages\flask\helpers.py", line 338, in url_for
    return appctx.app.handle_url_build_error(error, endpoint, values)
  File "c:\users\user\anaconda3\envs\web\lib\site-packages\flask\helpers.py", line 325, in url_for
    rv = url_adapter.build(
  File "c:\users\user\anaconda3\envs\web\lib\site-packages\werkzeug\routing.py", line 2305, in build
    raise BuildError(endpoint, values, method, self)
werkzeug.routing.BuildError: Could not build url for endpoint 'main.ejecutivos'. Did you mean 'main.gestion' instead?
2021-06-28 16:16:09,410 INFO: Microblog startup [in C:\Users\user\Desktop\MTS\app\__init__.py:97]
2021-06-28 16:16:09,538 ERROR: Exception on /gestion [POST] [in c:\users\user\anaconda3\envs\web\lib\site-packages\flask\app.py:1454]
Traceback (most recent call last):
  File "c:\users\user\anaconda3\envs\web\lib\site-packages\flask\app.py", line 2070, in wsgi_app
    response = self.full_dispatch_request()
  File "c:\users\user\anaconda3\envs\web\lib\site-packages\flask\app.py", line 1515, in full_dispatch_request
    rv = self.handle_user_exception(e)
  File "c:\users\user\anaconda3\envs\web\lib\site-packages\flask\app.py", line 1513, in full_dispatch_request
    rv = self.dispatch_request()
  File "c:\users\user\anaconda3\envs\web\lib\site-packages\flask\app.py", line 1499, in dispatch_request
    return self.ensure_sync(self.view_functions[rule.endpoint])(**req.view_args)
  File "c:\users\user\anaconda3\envs\web\lib\site-packages\flask_login\utils.py", line 272, in decorated_view
    return func(*args, **kwargs)
  File "C:\Users\user\Desktop\MTS\app\main\routes.py", line 42, in decorated_function
    return f(*args, **kws)
  File "C:\Users\user\Desktop\MTS\app\main\routes.py", line 301, in gestion
    return redirect(url_for('main.ejecutivos'))
  File "c:\users\user\anaconda3\envs\web\lib\site-packages\flask\helpers.py", line 338, in url_for
    return appctx.app.handle_url_build_error(error, endpoint, values)
  File "c:\users\user\anaconda3\envs\web\lib\site-packages\flask\helpers.py", line 325, in url_for
    rv = url_adapter.build(
  File "c:\users\user\anaconda3\envs\web\lib\site-packages\werkzeug\routing.py", line 2305, in build
    raise BuildError(endpoint, values, method, self)
werkzeug.routing.BuildError: Could not build url for endpoint 'main.ejecutivos'. Did you mean 'main.gestion' instead?
2021-06-28 16:17:36,259 INFO: Microblog startup [in C:\Users\user\Desktop\MTS\app\__init__.py:97]
2021-06-28 16:17:38,875 ERROR: Exception on /gestion [POST] [in c:\users\user\anaconda3\envs\web\lib\site-packages\flask\app.py:1454]
Traceback (most recent call last):
  File "c:\users\user\anaconda3\envs\web\lib\site-packages\flask\app.py", line 2070, in wsgi_app
    response = self.full_dispatch_request()
  File "c:\users\user\anaconda3\envs\web\lib\site-packages\flask\app.py", line 1515, in full_dispatch_request
    rv = self.handle_user_exception(e)
  File "c:\users\user\anaconda3\envs\web\lib\site-packages\flask\app.py", line 1513, in full_dispatch_request
    rv = self.dispatch_request()
  File "c:\users\user\anaconda3\envs\web\lib\site-packages\flask\app.py", line 1499, in dispatch_request
    return self.ensure_sync(self.view_functions[rule.endpoint])(**req.view_args)
  File "c:\users\user\anaconda3\envs\web\lib\site-packages\flask_login\utils.py", line 272, in decorated_view
    return func(*args, **kwargs)
  File "C:\Users\user\Desktop\MTS\app\main\routes.py", line 42, in decorated_function
    return f(*args, **kws)
  File "C:\Users\user\Desktop\MTS\app\main\routes.py", line 301, in gestion
    return redirect(url_for('main.ejecutivos'))
  File "c:\users\user\anaconda3\envs\web\lib\site-packages\flask\helpers.py", line 338, in url_for
    return appctx.app.handle_url_build_error(error, endpoint, values)
  File "c:\users\user\anaconda3\envs\web\lib\site-packages\flask\helpers.py", line 325, in url_for
    rv = url_adapter.build(
  File "c:\users\user\anaconda3\envs\web\lib\site-packages\werkzeug\routing.py", line 2305, in build
    raise BuildError(endpoint, values, method, self)
werkzeug.routing.BuildError: Could not build url for endpoint 'main.ejecutivos'. Did you mean 'main.gestion' instead?
2021-06-28 16:18:56,064 INFO: Microblog startup [in C:\Users\user\Desktop\MTS\app\__init__.py:97]
2021-06-28 16:18:58,725 ERROR: Exception on /gestion [POST] [in c:\users\user\anaconda3\envs\web\lib\site-packages\flask\app.py:1454]
Traceback (most recent call last):
  File "c:\users\user\anaconda3\envs\web\lib\site-packages\flask\app.py", line 2070, in wsgi_app
    response = self.full_dispatch_request()
  File "c:\users\user\anaconda3\envs\web\lib\site-packages\flask\app.py", line 1515, in full_dispatch_request
    rv = self.handle_user_exception(e)
  File "c:\users\user\anaconda3\envs\web\lib\site-packages\flask\app.py", line 1513, in full_dispatch_request
    rv = self.dispatch_request()
  File "c:\users\user\anaconda3\envs\web\lib\site-packages\flask\app.py", line 1499, in dispatch_request
    return self.ensure_sync(self.view_functions[rule.endpoint])(**req.view_args)
  File "c:\users\user\anaconda3\envs\web\lib\site-packages\flask_login\utils.py", line 272, in decorated_view
    return func(*args, **kwargs)
  File "C:\Users\user\Desktop\MTS\app\main\routes.py", line 42, in decorated_function
    return f(*args, **kws)
  File "C:\Users\user\Desktop\MTS\app\main\routes.py", line 301, in gestion
    return redirect(url_for('main.historal'))
  File "c:\users\user\anaconda3\envs\web\lib\site-packages\flask\helpers.py", line 338, in url_for
    return appctx.app.handle_url_build_error(error, endpoint, values)
  File "c:\users\user\anaconda3\envs\web\lib\site-packages\flask\helpers.py", line 325, in url_for
    rv = url_adapter.build(
  File "c:\users\user\anaconda3\envs\web\lib\site-packages\werkzeug\routing.py", line 2305, in build
    raise BuildError(endpoint, values, method, self)
werkzeug.routing.BuildError: Could not build url for endpoint 'main.historal'. Did you mean 'main.historial' instead?
2021-06-28 16:19:48,195 INFO: Microblog startup [in C:\Users\user\Desktop\MTS\app\__init__.py:97]
2021-06-28 16:20:49,089 INFO: Microblog startup [in C:\Users\user\Desktop\MTS\app\__init__.py:97]
2021-06-28 16:25:01,060 INFO: Microblog startup [in C:\Users\user\Desktop\MTS\app\__init__.py:97]
2021-06-28 16:26:53,261 INFO: Microblog startup [in C:\Users\user\Desktop\MTS\app\__init__.py:97]
2021-06-28 16:27:02,499 INFO: Microblog startup [in C:\Users\user\Desktop\MTS\app\__init__.py:97]
2021-06-28 16:27:20,258 INFO: Microblog startup [in C:\Users\user\Desktop\MTS\app\__init__.py:97]
2021-06-28 16:31:44,094 INFO: Microblog startup [in C:\Users\user\Desktop\MTS\app\__init__.py:97]
2021-06-28 16:40:09,717 INFO: Microblog startup [in C:\Users\user\Desktop\MTS\app\__init__.py:97]
